<?xml version="1.0" ?>
<!-- =================================================================================== -->
<!-- |    This document was autogenerated by xacro from differential_robot.urdf        | -->
<!-- |    EDITING THIS FILE BY HAND IS NOT RECOMMENDED                                 | -->
<!-- =================================================================================== -->
<robot name="my_robot" xmlns:xacro="http://ros.org/wiki/xacro">
  <material name="blue">
    <color rgba="0 0 0.8 1"/>
  </material>
  <material name="black">
    <color rgba="0 0 0 1"/>
  </material>
  <material name="white">
    <color rgba="1 1 1 1"/>
  </material>
  <material name="red">
    <color rgba="1 0 0 1"/>
  </material>
  <link name="base_link">
    <visual>
      <geometry>
        <cylinder length="0.02" radius="0.0825"/>
      </geometry>
      <material name="red"/>
    </visual>
    <collision>
      <geometry>
        <cylinder length="0.02" radius="0.0825"/>
      </geometry>
    </collision>
    <inertial>
      <mass value="0.1"/>
      <inertia ixx="0.00017" ixy="0.0" ixz="0.0" iyy="0.00017" iyz="0.0" izz="0.00034"/>
    </inertial>
  </link>
  <link name="left_wheel">
    <visual>
      <geometry>
        <cylinder length="0.008" radius="0.035"/>
      </geometry>
      <material name="black"/>
      <origin rpy="1.57079632679 0 0" xyz="0 0 0"/>
    </visual>
    <collision>
      <geometry>
        <cylinder length="0.008" radius="0.035"/>
      </geometry>
      <origin rpy="1.57079632679 0 0" xyz="0 0 0"/>
    </collision>
    <inertial>
      <mass value="0.015"/>
      <inertia ixx="0.0000092" ixy="0.0" ixz="0.0" iyy="0.0000047" iyz="0.0" izz="0.0000047"/>
    </inertial>
  </link>
  <joint name="base_to_left_wheel" type="continuous">
    <parent link="base_link"/>
    <child link="left_wheel"/>
    <axis xyz="0 1 0"/>
    <origin xyz="0 0.0825 0"/>
  </joint>
  <link name="right_wheel">
    <visual>
      <geometry>
        <cylinder length="0.008" radius="0.035"/>
      </geometry>
      <material name="black"/>
      <origin rpy="1.57079632679 0 0" xyz="0 0 0"/>
    </visual>
    <collision>
      <geometry>
        <cylinder length="0.008" radius="0.035"/>
      </geometry>
      <origin rpy="1.57079632679 0 0" xyz="0 0 0"/>
    </collision>
    <inertial>
      <mass value="0.015"/>
      <inertia ixx="0.0000092" ixy="0.0" ixz="0.0" iyy="0.0000047" iyz="0.0" izz="0.0000047"/>
    </inertial>
  </link>
  <joint name="base_to_right_wheel" type="continuous">
    <parent link="base_link"/>
    <child link="right_wheel"/>
    <axis xyz="0 1 0"/>
    <origin xyz="0 -0.0825 0"/>
  </joint>
  <link name="head">
    <visual>
      <geometry>
        <box size="0.03 0.03 0.03"/>
      </geometry>
      <material name="blue"/>
      <origin xyz="0.015 0 0.015"/>
    </visual>
    <collision>
      <geometry>
        <box size="0.03 0.03 0.03"/>
      </geometry>
      <origin xyz="0.015 0 0.015"/>
    </collision>
    <inertial>
      <mass value="0.02"/>
      <inertia ixx="0.000003" ixy="0.0" ixz="0.0" iyy="0.000003" iyz="0.0" izz="0.000003"/>
    </inertial>
  </link>
  <joint name="tohead" type="fixed">
    <parent link="base_link"/>
    <child link="head"/>
    <origin xyz="0.0525 0 0.01"/>
  </joint>
  <link name="base_footprint">
  </link>
  <joint name="footprinttobase" type="fixed">
    <parent link="base_footprint"/>
    <child link="base_link"/>
    <origin xyz="0 0 0.035"/>
  </joint>
  <!-- Gazebo plugin for ROS Control -->
  <gazebo>
    <plugin filename="libgazebo_ros_control.so" name="gazebo_ros_control">
      <robotNamespace>/</robotNamespace>
    </plugin>
  </gazebo>
</robot>

